[2024-09-03T02:19:50.907+0000] {local_task_job_runner.py:120} INFO - ::group::Pre task execution logs
[2024-09-03T02:19:50.926+0000] {taskinstance.py:2076} INFO - Dependencies all met for dep_context=non-requeueable deps ti=<TaskInstance: redshift_etl_dag.extrear_datos_API scheduled__2024-09-02T00:00:00+00:00 [queued]>
[2024-09-03T02:19:50.935+0000] {taskinstance.py:2076} INFO - Dependencies all met for dep_context=requeueable deps ti=<TaskInstance: redshift_etl_dag.extrear_datos_API scheduled__2024-09-02T00:00:00+00:00 [queued]>
[2024-09-03T02:19:50.936+0000] {taskinstance.py:2306} INFO - Starting attempt 4 of 6
[2024-09-03T02:19:50.952+0000] {taskinstance.py:2330} INFO - Executing <Task(PythonOperator): extrear_datos_API> on 2024-09-02 00:00:00+00:00
[2024-09-03T02:19:50.958+0000] {warnings.py:112} WARNING - /home/***/.local/lib/python3.12/site-packages/***/task/task_runner/standard_task_runner.py:61: DeprecationWarning: This process (pid=63) is multi-threaded, use of fork() may lead to deadlocks in the child.
  pid = os.fork()

[2024-09-03T02:19:50.961+0000] {standard_task_runner.py:63} INFO - Started process 68 to run task
[2024-09-03T02:19:50.961+0000] {standard_task_runner.py:90} INFO - Running: ['***', 'tasks', 'run', 'redshift_etl_dag', 'extrear_datos_API', 'scheduled__2024-09-02T00:00:00+00:00', '--job-id', '31', '--raw', '--subdir', 'DAGS_FOLDER/dag_etl.py', '--cfg-path', '/tmp/tmpzs_ygimg']
[2024-09-03T02:19:50.964+0000] {standard_task_runner.py:91} INFO - Job 31: Subtask extrear_datos_API
[2024-09-03T02:19:51.019+0000] {task_command.py:426} INFO - Running <TaskInstance: redshift_etl_dag.extrear_datos_API scheduled__2024-09-02T00:00:00+00:00 [running]> on host 9110929bbae0
[2024-09-03T02:19:51.104+0000] {taskinstance.py:2648} INFO - Exporting env vars: AIRFLOW_CTX_DAG_OWNER='jose_araya' AIRFLOW_CTX_DAG_ID='redshift_etl_dag' AIRFLOW_CTX_TASK_ID='extrear_datos_API' AIRFLOW_CTX_EXECUTION_DATE='2024-09-02T00:00:00+00:00' AIRFLOW_CTX_TRY_NUMBER='4' AIRFLOW_CTX_DAG_RUN_ID='scheduled__2024-09-02T00:00:00+00:00'
[2024-09-03T02:19:51.106+0000] {taskinstance.py:430} INFO - ::endgroup::
[2024-09-03T02:19:54.065+0000] {taskinstance.py:441} INFO - ::group::Post task execution logs
[2024-09-03T02:19:54.066+0000] {taskinstance.py:2905} ERROR - Task failed with exception
Traceback (most recent call last):
  File "/home/airflow/.local/lib/python3.12/site-packages/airflow/models/taskinstance.py", line 465, in _execute_task
    result = _execute_callable(context=context, **execute_callable_kwargs)
             ^^^^^^^^^^^^^^^^^^^^^^^^^^^^^^^^^^^^^^^^^^^^^^^^^^^^^^^^^^^^^
  File "/home/airflow/.local/lib/python3.12/site-packages/airflow/models/taskinstance.py", line 432, in _execute_callable
    return execute_callable(context=context, **execute_callable_kwargs)
           ^^^^^^^^^^^^^^^^^^^^^^^^^^^^^^^^^^^^^^^^^^^^^^^^^^^^^^^^^^^^
  File "/home/airflow/.local/lib/python3.12/site-packages/airflow/models/baseoperator.py", line 401, in wrapper
    return func(self, *args, **kwargs)
           ^^^^^^^^^^^^^^^^^^^^^^^^^^^
  File "/home/airflow/.local/lib/python3.12/site-packages/airflow/operators/python.py", line 235, in execute
    return_value = self.execute_callable()
                   ^^^^^^^^^^^^^^^^^^^^^^^
  File "/home/airflow/.local/lib/python3.12/site-packages/airflow/operators/python.py", line 252, in execute_callable
    return self.python_callable(*self.op_args, **self.op_kwargs)
           ^^^^^^^^^^^^^^^^^^^^^^^^^^^^^^^^^^^^^^^^^^^^^^^^^^^^^
  File "/opt/airflow/dags/dag_etl.py", line 9, in extraer_datos_API
    api_instance.getdata()
  File "/opt/airflow/dags/modules/import_api.py", line 17, in getdata
    df.to_csv('./temp/df_pandas.csv')
  File "/home/airflow/.local/lib/python3.12/site-packages/pandas/core/generic.py", line 3902, in to_csv
    return DataFrameRenderer(formatter).to_csv(
           ^^^^^^^^^^^^^^^^^^^^^^^^^^^^^^^^^^^^
  File "/home/airflow/.local/lib/python3.12/site-packages/pandas/io/formats/format.py", line 1152, in to_csv
    csv_formatter.save()
  File "/home/airflow/.local/lib/python3.12/site-packages/pandas/io/formats/csvs.py", line 247, in save
    with get_handle(
         ^^^^^^^^^^^
  File "/home/airflow/.local/lib/python3.12/site-packages/pandas/io/common.py", line 739, in get_handle
    check_parent_directory(str(handle))
  File "/home/airflow/.local/lib/python3.12/site-packages/pandas/io/common.py", line 604, in check_parent_directory
    raise OSError(rf"Cannot save file into a non-existent directory: '{parent}'")
OSError: Cannot save file into a non-existent directory: 'temp'
[2024-09-03T02:19:54.086+0000] {taskinstance.py:1206} INFO - Marking task as UP_FOR_RETRY. dag_id=redshift_etl_dag, task_id=extrear_datos_API, run_id=scheduled__2024-09-02T00:00:00+00:00, execution_date=20240902T000000, start_date=20240903T021950, end_date=20240903T021954
[2024-09-03T02:19:54.097+0000] {standard_task_runner.py:110} ERROR - Failed to execute job 31 for task extrear_datos_API (Cannot save file into a non-existent directory: 'temp'; 68)
[2024-09-03T02:19:54.112+0000] {local_task_job_runner.py:240} INFO - Task exited with return code 1
[2024-09-03T02:19:54.133+0000] {taskinstance.py:3503} INFO - 0 downstream tasks scheduled from follow-on schedule check
[2024-09-03T02:19:54.136+0000] {local_task_job_runner.py:222} INFO - ::endgroup::
