[2024-09-03T02:35:12.001+0000] {local_task_job_runner.py:120} INFO - ::group::Pre task execution logs
[2024-09-03T02:35:12.022+0000] {taskinstance.py:2076} INFO - Dependencies all met for dep_context=non-requeueable deps ti=<TaskInstance: redshift_etl_dag.cargar_datos manual__2024-09-03T02:10:38.592145+00:00 [queued]>
[2024-09-03T02:35:12.031+0000] {taskinstance.py:2076} INFO - Dependencies all met for dep_context=requeueable deps ti=<TaskInstance: redshift_etl_dag.cargar_datos manual__2024-09-03T02:10:38.592145+00:00 [queued]>
[2024-09-03T02:35:12.033+0000] {taskinstance.py:2306} INFO - Starting attempt 5 of 6
[2024-09-03T02:35:12.048+0000] {taskinstance.py:2330} INFO - Executing <Task(PythonOperator): cargar_datos> on 2024-09-03 02:10:38.592145+00:00
[2024-09-03T02:35:12.054+0000] {warnings.py:112} WARNING - /home/***/.local/lib/python3.12/site-packages/***/task/task_runner/standard_task_runner.py:61: DeprecationWarning: This process (pid=159) is multi-threaded, use of fork() may lead to deadlocks in the child.
  pid = os.fork()

[2024-09-03T02:35:12.056+0000] {standard_task_runner.py:63} INFO - Started process 164 to run task
[2024-09-03T02:35:12.056+0000] {standard_task_runner.py:90} INFO - Running: ['***', 'tasks', 'run', 'redshift_etl_dag', 'cargar_datos', 'manual__2024-09-03T02:10:38.592145+00:00', '--job-id', '47', '--raw', '--subdir', 'DAGS_FOLDER/dag_etl.py', '--cfg-path', '/tmp/tmpge78dwa4']
[2024-09-03T02:35:12.059+0000] {standard_task_runner.py:91} INFO - Job 47: Subtask cargar_datos
[2024-09-03T02:35:12.166+0000] {task_command.py:426} INFO - Running <TaskInstance: redshift_etl_dag.cargar_datos manual__2024-09-03T02:10:38.592145+00:00 [running]> on host 117a0e03c003
[2024-09-03T02:35:12.375+0000] {taskinstance.py:2648} INFO - Exporting env vars: AIRFLOW_CTX_DAG_OWNER='jose_araya' AIRFLOW_CTX_DAG_ID='redshift_etl_dag' AIRFLOW_CTX_TASK_ID='cargar_datos' AIRFLOW_CTX_EXECUTION_DATE='2024-09-03T02:10:38.592145+00:00' AIRFLOW_CTX_TRY_NUMBER='5' AIRFLOW_CTX_DAG_RUN_ID='manual__2024-09-03T02:10:38.592145+00:00'
[2024-09-03T02:35:12.384+0000] {taskinstance.py:430} INFO - ::endgroup::
[2024-09-03T02:35:12.483+0000] {taskinstance.py:441} INFO - ::group::Post task execution logs
[2024-09-03T02:35:12.500+0000] {taskinstance.py:2905} ERROR - Task failed with exception
Traceback (most recent call last):
  File "/home/airflow/.local/lib/python3.12/site-packages/airflow/models/taskinstance.py", line 465, in _execute_task
    result = _execute_callable(context=context, **execute_callable_kwargs)
             ^^^^^^^^^^^^^^^^^^^^^^^^^^^^^^^^^^^^^^^^^^^^^^^^^^^^^^^^^^^^^
  File "/home/airflow/.local/lib/python3.12/site-packages/airflow/models/taskinstance.py", line 432, in _execute_callable
    return execute_callable(context=context, **execute_callable_kwargs)
           ^^^^^^^^^^^^^^^^^^^^^^^^^^^^^^^^^^^^^^^^^^^^^^^^^^^^^^^^^^^^
  File "/home/airflow/.local/lib/python3.12/site-packages/airflow/models/baseoperator.py", line 401, in wrapper
    return func(self, *args, **kwargs)
           ^^^^^^^^^^^^^^^^^^^^^^^^^^^
  File "/home/airflow/.local/lib/python3.12/site-packages/airflow/operators/python.py", line 235, in execute
    return_value = self.execute_callable()
                   ^^^^^^^^^^^^^^^^^^^^^^^
  File "/home/airflow/.local/lib/python3.12/site-packages/airflow/operators/python.py", line 252, in execute_callable
    return self.python_callable(*self.op_args, **self.op_kwargs)
           ^^^^^^^^^^^^^^^^^^^^^^^^^^^^^^^^^^^^^^^^^^^^^^^^^^^^^
  File "/opt/airflow/dags/dag_etl.py", line 13, in carga_datos_task
    carga_datos_instanciado.carga_datos()
  File "/opt/airflow/dags/modules/cargar_data.py", line 11, in carga_datos
    engine = hook.get_sqlalchemy_engine()
             ^^^^^^^^^^^^^^^^^^^^^^^^^^^^
  File "/home/airflow/.local/lib/python3.12/site-packages/airflow/providers/amazon/aws/hooks/redshift_sql.py", line 163, in get_sqlalchemy_engine
    conn_kwargs = self.conn.extra_dejson
                  ^^^^^^^^^
  File "/usr/local/lib/python3.12/functools.py", line 995, in __get__
    val = self.func(instance)
          ^^^^^^^^^^^^^^^^^^^
  File "/home/airflow/.local/lib/python3.12/site-packages/airflow/providers/amazon/aws/hooks/redshift_sql.py", line 76, in conn
    return self.get_connection(self.redshift_conn_id)  # type: ignore[attr-defined]
           ^^^^^^^^^^^^^^^^^^^^^^^^^^^^^^^^^^^^^^^^^^
  File "/home/airflow/.local/lib/python3.12/site-packages/airflow/hooks/base.py", line 83, in get_connection
    conn = Connection.get_connection_from_secrets(conn_id)
           ^^^^^^^^^^^^^^^^^^^^^^^^^^^^^^^^^^^^^^^^^^^^^^^
  File "/home/airflow/.local/lib/python3.12/site-packages/airflow/models/connection.py", line 519, in get_connection_from_secrets
    raise AirflowNotFoundException(f"The conn_id `{conn_id}` isn't defined")
airflow.exceptions.AirflowNotFoundException: The conn_id `redshift_default` isn't defined
[2024-09-03T02:35:12.530+0000] {taskinstance.py:1206} INFO - Marking task as UP_FOR_RETRY. dag_id=redshift_etl_dag, task_id=cargar_datos, run_id=manual__2024-09-03T02:10:38.592145+00:00, execution_date=20240903T021038, start_date=20240903T023512, end_date=20240903T023512
[2024-09-03T02:35:12.552+0000] {standard_task_runner.py:110} ERROR - Failed to execute job 47 for task cargar_datos (The conn_id `redshift_default` isn't defined; 164)
[2024-09-03T02:35:12.592+0000] {local_task_job_runner.py:240} INFO - Task exited with return code 1
[2024-09-03T02:35:12.611+0000] {taskinstance.py:3503} INFO - 0 downstream tasks scheduled from follow-on schedule check
[2024-09-03T02:35:12.613+0000] {local_task_job_runner.py:222} INFO - ::endgroup::
